<?xml version="1.0" ?>
<robot name="valkyrie" xmlns:xacro="http://ros.org/wiki/xacro">
  <!-- Head Link Simple Collision Meshes -->

  <link name="head">
    <inertial>
      <origin rpy="0 0 0" xyz="-0.075493 3.3383E-05 0.02774"/>
      <mass value="1.41984"/>
      <inertia ixx="0.0039688" ixy="-1.5797E-06" ixz="-0.00089293" iyy="0.0041178" iyz="-6.8415E-07" izz="0.0035243"/>
    </inertial>
    <!--     <visual>
      <origin xyz="0 0 0" rpy="0 0 0" />
      <geometry>
        <mesh filename="package://val_desc/model/meshes/multisense/head.dae" />
      </geometry>
      <material name="">
        <color rgba="0.9098 0.44314 0.031373 1" />
      </material>
    </visual> -->
    <collision>
      <origin rpy="0 0 0" xyz="-0.0503 0 0."/>
      <geometry>
        <!-- <box size="0.1311 0.12 0.0591"/> -->
        <box size="0.1311 0.12 0.15"/>
      </geometry>
    </collision>
    <collision>
      <origin rpy="0 0 0" xyz="-0.2 0 0.0868"/>
      <geometry>
        <sphere radius="0.05"/>
      </geometry>
    </collision>
    <collision>
      <origin rpy="0 0 0" xyz="0.002 0 0.19"/>
      <geometry>
        <sphere radius="0.0325"/>
      </geometry>
    </collision>
  </link>

  <link name="pelvis">
    <inertial>
      <mass value="8.22"/>
      <origin rpy="0 0 0" xyz="-0.00532 -0.003512 -0.0036"/>
      <inertia ixx="0.11866378" ixy="-0.000143482" ixz="0.003271293" iyy="0.097963425" iyz="0.002159545" izz="0.083854638"/>
    </inertial>
    <visual>
      <geometry>
        <mesh filename="package://val_desc/model/meshes/pelvis/pelvis.dae"/>
      </geometry>
      <origin rpy="0.0 0.0 0.0" xyz="0.0 0.0 0.0"/>
    </visual>
    <collision>
      <geometry>
        <box size="0.2 0.25 0.25"/>
      </geometry>
      <origin rpy="0 0 0" xyz="0 0 -0.15"/> 
    </collision>
  </link>
  <link name="torsoYawLink">
    <inertial>
      <mass value="0.5"/>
      <origin rpy="0 0 0" xyz="0.000000 0.000000 -0.010000"/>
      <inertia ixx="0.000608427" ixy="-1.172e-06" ixz="1.647e-06" iyy="0.000620328" iyz="-2.33e-07" izz="0.001078108"/>
    </inertial>
    <visual>
      <geometry>
        <mesh filename="package://val_desc/model/meshes/torso/torsoyaw.dae"/>
      </geometry>
      <origin rpy="0.0 0.0 0.0" xyz="0.0 0.0 0.0"/>
    </visual>
  </link>
  <link name="torsoPitchLink">
    <inertial>
      <mass value="0.1"/>
      <origin rpy="0 0 0" xyz="0.000000 0.000000  0.005000"/>
      <inertia ixx="3.032e-05" ixy="0.0" ixz="-1.145e-06" iyy="2.1274e-05" iyz="0.0" izz="2.8285e-05"/>
    </inertial>
    <visual>
      <geometry>
        <mesh filename="package://val_desc/model/meshes/torso/torsopitch.dae"/>
      </geometry>
      <origin rpy="0.0 0.0 0.0" xyz="0.0 0.0 0.0"/>
    </visual>
  </link>
  <link name="torso">
    <inertial>
      <mass value="39.47"/>
      <origin rpy="0 0 0" xyz="-0.095548 -0.003337 0.243098"/>
      <inertia ixx="0.87326933" ixy="9.9563e-05" ixz="0.061345211" iyy="1.0108485" iyz="0.00181849" izz="0.77839801"/>
    </inertial>
    <visual>
      <geometry>
        <mesh filename="package://val_desc/model/meshes/torso/torso.dae"/>
      </geometry>
      <origin rpy="0.0 0.0 0.0" xyz="0.05 0.0 0.0"/>
    </visual>
    <collision name="torso_mid">
      <geometry>
        <box size="0.225 0.25 0.075"/>
      </geometry>
      <origin rpy="0 0 0" xyz="0.05 0 0.26"/>
    </collision>
    <collision name="torso_upper_mid">
      <geometry>
        <box size="0.22 0.225 0.02"/>
      </geometry>
      <origin rpy="0 0 0" xyz="0.05 0 0.31"/>
    </collision>
    <collision name="torso_upper">
      <geometry>
        <box size="0.125 0.225 0.05"/>
      </geometry>
      <origin rpy="0 0 0" xyz="-0.03 0 0.35"/>
    </collision>
    <collision name="backpack">
      <geometry>
        <box size="0.14 0.255 0.34"/>
      </geometry>
      <origin rpy="0 0 0" xyz="-0.16 0 0.22"/>
    </collision>
    <collision name="torso_lower">
      <geometry>
        <box size="0.2 0.2 0.2"/>
      </geometry>
      <origin rpy="0 0 0" xyz="0.025 0 0.125"/>
    </collision>
  </link>
  <joint name="torsoYaw" type="revolute">
    <origin rpy="0.0 0.0 0.0" xyz="0.0 0.0 0.0"/>
    <axis xyz="0 0 1"/>
    <parent link="pelvis"/>
    <child link="torsoYawLink"/>
    <limit effort="190" lower="-1.329" upper="1.181" velocity="5.89"/>
    <controller_gains Kd="0.0" Ki="0.0" Kp="0.0"/>
    <dynamics damping="0.1" friction="0.0"/>
  </joint>
  <gazebo reference="torsoYaw">
    <provideFeedback>1</provideFeedback>
    <implicitSpringDamper>1</implicitSpringDamper>
  </gazebo>
  <joint name="torsoPitch" type="revolute">
    <origin rpy="0.0 0.0 0.0" xyz="0.04191 0.0 0.0"/>
    <axis xyz="0 1 0"/>
    <parent link="torsoYawLink"/>
    <child link="torsoPitchLink"/>
    <limit effort="150" lower="-0.13" upper="0.666" velocity="9"/>
    <controller_gains Kd="0.0" Ki="0.0" Kp="0.0"/>
    <dynamics damping="0.1" friction="0.0"/>
  </joint>
  <gazebo reference="torsoPitch">
    <provideFeedback>1</provideFeedback>
    <implicitSpringDamper>1</implicitSpringDamper>
  </gazebo>
  <joint name="torsoRoll" type="revolute">
    <origin rpy="0.0 0.0 0.0" xyz="0.0 0.0 0.0203"/>
    <axis xyz="1 0 0"/>
    <parent link="torsoPitchLink"/>
    <child link="torso"/>
    <limit effort="150" lower="-0.23" upper="0.255" velocity="9"/>
    <controller_gains Kd="0.0" Ki="0.0" Kp="0.0"/>
    <dynamics damping="0.1" friction="0.0"/>
  </joint>
  <gazebo reference="torsoRoll">
    <provideFeedback>1</provideFeedback>
    <implicitSpringDamper>1</implicitSpringDamper>
  </gazebo>
  <link name="lowerNeckPitchLink">
    <inertial>
      <mass value="1.05"/>
      <origin rpy="0 0 0" xyz="-0.020000 0.000000  0.040000"/>
      <inertia ixx="0.001470716" ixy="-0.000126021" ixz="0.000632521" iyy="0.001851919" iyz="0.000243012" izz="0.000832117"/>
    </inertial>
    <visual>
      <geometry>
        <mesh filename="package://val_desc/model/meshes/head/neckj1.dae"/>
      </geometry>
      <origin rpy="0.0 0.0 0.0" xyz="0.0 0.0 0.0"/>
    </visual>
  </link>
  <link name="neckYawLink">
    <inertial>
      <mass value="1.4"/>
      <origin rpy="0 0 0" xyz="-0.03  -0.01 0.15"/>
      <inertia ixx="0.001997698" ixy="-0.000180062" ixz="0.000723677" iyy="0.002919928" iyz="0.000246467" izz="0.002119751"/>
    </inertial>
    <visual>
      <geometry>
        <mesh filename="package://val_desc/model/meshes/head/neckj2.dae"/>
      </geometry>
      <origin rpy="0.0 0.0 0.0" xyz="0.0 0.0 0.0"/>
    </visual>
    <collision>
      <geometry>
        <sphere radius="0.0325"/>
      </geometry>
      <origin rpy="0 0 0" xyz="0 0 0.1"/>
    </collision>
  </link>
  <link name="upperNeckPitchLink">
    <inertial>
      <mass value="3.89"/>
      <origin rpy="0 0 0" xyz="0.100912 0.005783 0.034787"/>
      <inertia ixx="0.039847525" ixy="-0.000470418" ixz="-0.002829842" iyy="0.041418564" iyz="-0.000782564" izz="0.036841236"/>
    </inertial>
    <visual>
      <geometry>
        <mesh filename="package://val_desc/model/meshes/head/head_multisense_no_visor.dae"/>
      </geometry>
      <origin rpy="0.0 0.0 0.0" xyz="0.0 0.0 0.0"/>
    </visual>
  </link>
  <joint name="lowerNeckPitch" type="revolute">
    <origin rpy="0.0 0.0 0.0" xyz="0.0203518 0.0 0.33845"/>
    <axis xyz="0 1 0"/>
    <parent link="torso"/>
    <child link="lowerNeckPitchLink"/>
    <limit effort="26" lower="0" upper="1.162" velocity="5"/>
    <controller_gains Kd="400" Ki="0.0" Kp="20000"/>
    <dynamics damping="0.1" friction="0.0"/>
  </joint>
  <gazebo reference="lowerNeckPitch">
    <provideFeedback>1</provideFeedback>
    <implicitSpringDamper>1</implicitSpringDamper>
  </gazebo>
  <joint name="neckYaw" type="revolute">
    <origin rpy="0.0 0.0 0.0" xyz="-0.051924 0.0 0.0"/>
    <axis xyz="0 0 1"/>
    <parent link="lowerNeckPitchLink"/>
    <child link="neckYawLink"/>
    <limit effort="26" lower="-1.04719755" upper="1.04719755" velocity="5"/>
    <controller_gains Kd="400" Ki="0.0" Kp="20000"/>
    <dynamics damping="0.1" friction="0.0"/>
  </joint>
  <gazebo reference="neckYaw">
    <provideFeedback>1</provideFeedback>
    <implicitSpringDamper>1</implicitSpringDamper>
  </gazebo>
  <joint name="upperNeckPitch" type="revolute">
    <origin rpy="0.0 0.0 0.0" xyz="-0.06 0 0.195997"/>
    <axis xyz="0 1 0"/>
    <parent link="neckYawLink"/>
    <child link="upperNeckPitchLink"/>
    <limit effort="26" lower="-0.872" upper="0.0" velocity="5"/>
    <controller_gains Kd="400" Ki="0.0" Kp="20000"/>
    <dynamics damping="0.1" friction="0.0"/>
  </joint>
  <gazebo reference="upperNeckPitch">
    <provideFeedback>1</provideFeedback>
    <implicitSpringDamper>1</implicitSpringDamper>
  </gazebo>
  <link name="rightShoulderPitchLink">
    <inertial>
      <mass value="2.65"/>
      <origin rpy="0 0 0" xyz="0.012 -0.251 0.000000"/>
      <inertia ixx="0.013718167" ixy="0.0" ixz="0.0" iyy="0.010502833" iyz="0.0" izz="0.014806433"/>
    </inertial>
    <visual>
      <geometry>
        <mesh filename="package://val_desc/model/meshes/arms/aj1_right.dae"/>
      </geometry>
      <origin rpy="0.0 0.0 0.0" xyz="0.0 0.0 0.0"/>
    </visual>
  </link>
  <link name="rightShoulderRollLink">
    <inertial>
      <mass value="3.97"/>
      <origin rpy="0 0 0" xyz="0.008513 -0.02068 -0.001088"/>
      <inertia ixx="0.014598842" ixy="-0.00066764" ixz="3.629e-05" iyy="0.006452136" iyz="8.283e-05" izz="0.016848319"/>
    </inertial>
    <visual>
      <geometry>
        <mesh filename="package://val_desc/model/meshes/arms/aj2_right.dae"/>
      </geometry>
      <origin rpy="0.0 0.0 0.0" xyz="0.0 0.0 0.0"/>
    </visual>
    <collision name="rightShoulderRollLink_test">
      <geometry>
        <!-- <mesh filename="package://val_desc/model/meshes/arms/aj2_right.dae"/> 0.176 -->
        <cylinder radius="0.06" length="0.186"/>
      </geometry>
      <origin rpy="1.57 0 0" xyz="0 -0.145 0"/>
    </collision>
    <collision_checking>
      <capsule name="rightShoulderRollLink_test"/>
    </collision_checking>
  </link>
  <link name="rightShoulderYawLink">
    <inertial>
      <mass value="3.085"/>
      <origin rpy="0 0 0" xyz="-0.004304 -0.209832 -0.007295"/>
      <inertia ixx="0.039355177" ixy="0.007827077" ixz="0.000753947" iyy="0.004905765" iyz="-0.002723873" izz="0.041879481"/>
    </inertial>
    <visual>
      <geometry>
        <mesh filename="package://val_desc/model/meshes/arms/aj3_right.dae"/>
      </geometry>
      <origin rpy="0.0 0.0 0.0" xyz="0.0 0.0 0.0"/>
    </visual>
  </link>
  <link name="rightElbowPitchLink">
    <inertial>
      <mass value="1.83"/>
      <origin rpy="0 0 0" xyz="-0.020344 -0.014722 -0.0223"/>
      <inertia ixx="0.003314516" ixy="-0.000535099" ixz="-0.000728077" iyy="0.003505669" iyz="-0.000423865" izz="0.003011283"/>
    </inertial>
    <visual>
      <geometry>
        <mesh filename="package://val_desc/model/meshes/arms/aj4_right.dae"/>
      </geometry>
      <origin rpy="0.0 0.0 0.0" xyz="0.0 0.0 0.0"/>
    </visual>
  </link>
  <joint name="rightShoulderPitch" type="revolute">
    <origin rpy="0.0 0.0 0.0" xyz="-0.0316 0.0 0.2984"/>
    <axis xyz="0 1 0"/>
    <parent link="torso"/>
    <child link="rightShoulderPitchLink"/>
    <limit effort="190" lower="-2.85" upper="2.0" velocity="5.89"/>
    <controller_gains Kd="0.0" Ki="0.0" Kp="0.0"/>
    <dynamics damping="0.1" friction="0.0"/>
  </joint>
  <gazebo reference="rightShoulderPitch">
    <provideFeedback>1</provideFeedback>
    <implicitSpringDamper>1</implicitSpringDamper>
  </gazebo>
  <joint name="rightShoulderRoll" type="revolute">
    <origin rpy="0.0 0.0 0.0" xyz="0.0 -0.2499 0.0"/>
    <axis xyz="1 0 0"/>
    <parent link="rightShoulderPitchLink"/>
    <child link="rightShoulderRollLink"/>
    <limit effort="190" lower="-1.266" upper="1.519" velocity="5.89"/>
    <controller_gains Kd="0.0" Ki="0.0" Kp="0.0"/>
    <dynamics damping="0.1" friction="0.0"/>
  </joint>
  <gazebo reference="rightShoulderRoll">
    <provideFeedback>1</provideFeedback>
    <implicitSpringDamper>1</implicitSpringDamper>
  </gazebo>
  <joint name="rightShoulderYaw" type="revolute">
    <origin rpy="0.0 0.0 0.0" xyz="0.0 0.0 0.0"/>
    <axis xyz="0 1 0"/>
    <parent link="rightShoulderRollLink"/>
    <child link="rightShoulderYawLink"/>
    <limit effort="65" lower="-3.1" upper="2.18" velocity="11.5"/>
    <controller_gains Kd="0.0" Ki="0.0" Kp="0.0"/>
    <dynamics damping="0.1" friction="0.0"/>
  </joint>
  <gazebo reference="rightShoulderYaw">
    <provideFeedback>1</provideFeedback>
    <implicitSpringDamper>1</implicitSpringDamper>
  </gazebo>
  <joint name="rightElbowPitch" type="revolute">
    <origin rpy="0.0 0.0 0.0" xyz="0.0254 -0.33 0.0"/>
    <axis xyz="0 0 1"/>
    <parent link="rightShoulderYawLink"/>
    <child link="rightElbowPitchLink"/>
    <limit effort="65" lower="-0.12" upper="2.174" velocity="11.5"/>
    <controller_gains Kd="0.0" Ki="0.0" Kp="0.0"/>
    <dynamics damping="0.1" friction="0.0"/>
  </joint>

  <joint name="rightElbowNear" type="fixed">
    <origin rpy="0.0 0.0 0.0" xyz="0.0254 -0.33 0.0"/>
    <axis xyz="0 0 1"/>
    <parent link="rightShoulderYawLink"/>
    <child link="rightElbowNearLink"/>
  </joint>
  <link name="rightElbowNearLink">
    <inertial>
      <mass value="0.0"/>
      <origin rpy="0 0 0" xyz="0.0 0.0 0.0"/>
      <inertia ixx="0.0" ixy="0.0" ixz="0.0" iyy="0.0" iyz="0.0" izz="0.0"/>
    </inertial>
    <collision>
      <geometry>
        <sphere radius="0.085"/>
      </geometry>
      <origin rpy="0.0 0 0" xyz="-0.02 0.0 0"/>
    </collision>
  </link>

  <gazebo reference="rightElbowPitch">
    <provideFeedback>1</provideFeedback>
    <implicitSpringDamper>1</implicitSpringDamper>
  </gazebo>
  <link name="rightForearmLink">
    <inertial>
      <mass value="2.476"/>
      <origin rpy="0 0 0" xyz="0.015000 -0.13 0.019564"/>
      <inertia ixx="0.01175543" ixy="-0.001300853" ixz="-0.000727141" iyy="0.005071567" iyz="-0.001695416" izz="0.011365657"/>
    </inertial>
    <visual>
      <geometry>
        <mesh filename="package://val_desc/model/meshes/arms/aj5_right.dae"/>
      </geometry>
      <origin rpy="0.0 0.0 0.0" xyz="0.0 0.0 0.0"/>
    </visual>
    <collision>
      <geometry>
        <cylinder radius="0.06" length="0.17"/>
      </geometry>
      <origin rpy="1.57 0 0" xyz="0 -0.155 0"/>
    </collision>
  </link>
  <link name="rightWristRollLink">
    <inertial>
      <mass value="0.14"/>
      <origin rpy="0 0 0" xyz="0 -0.0 0"/>
      <inertia ixx="3.0251e-05" ixy="-1.25e-07" ixz="-3.6e-08" iyy="3.772e-05" iyz="0.0" izz="9.395e-06"/>
    </inertial>
    <visual>
      <geometry>
        <mesh filename="package://val_desc/model/meshes/arms/aj6_right.dae"/>
      </geometry>
      <origin rpy="0.0 0.0 0.0" xyz="0.0 0.0 0.0"/>
    </visual>
  </link>
  <link name="rightPalm">
    <inertial>
      <mass value="0.712"/>
      <origin rpy="0 0 0" xyz="0.002954 -0.052034 -0.000236"/>
      <inertia ixx="0.000943493" ixy="3.4393e-05" ixz="-3.8828e-05" iyy="0.000711024" iyz="2.3429e-05" izz="0.000610199"/>
    </inertial>
    <visual>
      <geometry>
        <mesh filename="package://val_desc/model/meshes/arms/palm_right.dae"/>
      </geometry>
      <origin rpy="0.0 0.0 0.0" xyz="0.0 0.0 0.0"/>
    </visual>
    <collision>
      <geometry>
        <box size="0.05 0.075 0.0685"/>
      </geometry>
      <origin rpy="0 0 0" xyz="-0.0075 -0.06 0.0"/>
    </collision>
  </link>
  <joint name="rightForearmYaw" type="revolute">
    <origin rpy="0.0 0.0 0.0" xyz="-0.0254 0 0"/>
    <axis xyz="0 1 0"/>
    <parent link="rightElbowPitchLink"/>
    <child link="rightForearmLink"/>
    <limit effort="26" lower="-2.019" upper="3.14" velocity="5"/>
    <controller_gains Kd="0" Ki="0.0" Kp="0.0"/>
    <dynamics damping="0.1" friction="0.0"/>
  </joint>
  <gazebo reference="rightForearmYaw">
    <provideFeedback>1</provideFeedback>
    <implicitSpringDamper>1</implicitSpringDamper>
  </gazebo>
  <joint name="rightWristRoll" type="revolute">
    <origin rpy="0.0 0.0 0.0" xyz="0.0 -0.2871 0.0"/>
    <axis xyz="1 0 0"/>
    <parent link="rightForearmLink"/>
    <child link="rightWristRollLink"/>
    <!-- <limit effort="14" lower="-0.625" upper="0.62" velocity="1"/> -->
    <limit effort="14" lower="-4.14" upper="4.14" velocity="1"/>
    <controller_gains Kd="400" Ki="0.0" Kp="20000"/>
    <dynamics damping="0.1" friction="0.0"/>
  </joint>
  <gazebo reference="rightWristRoll">
    <provideFeedback>1</provideFeedback>
    <implicitSpringDamper>1</implicitSpringDamper>
  </gazebo>
  <joint name="rightWristPitch" type="revolute">
    <origin rpy="0.0 0.0 0.0" xyz="0.0 0.0 0.0"/>
    <axis xyz="0 0 1"/>
    <parent link="rightWristRollLink"/>
    <child link="rightPalm"/>
    <!-- <limit effort="14" lower="-0.49" upper="0.36" velocity="1"/> -->
    <limit effort="14" lower="-4.14" upper="4.14" velocity="1"/>
    <controller_gains Kd="400" Ki="0.0" Kp="20000"/>
    <dynamics damping="0.1" friction="0.0"/>
  </joint>
  <gazebo reference="rightWristPitch">
    <provideFeedback>1</provideFeedback>
    <implicitSpringDamper>1</implicitSpringDamper>
  </gazebo>

  <link name="leftShoulderPitchLink">
    <inertial>
      <mass value="2.65"/>
      <origin rpy="0 0 0" xyz="-0.012 0.251 0.000000"/>
      <inertia ixx="0.013718167" ixy="0.0" ixz="0.0" iyy="0.010502833" iyz="0.0" izz="0.014806433"/>
    </inertial>
    <visual>
      <geometry>
        <mesh filename="package://val_desc/model/meshes/arms/aj1_left.dae"/>
      </geometry>
      <origin rpy="0.0 0.0 0.0" xyz="0.0 0.0 0.0"/>
    </visual>
  </link>
  <link name="leftShoulderRollLink">
    <inertial>
      <mass value="3.97"/>
      <origin rpy="0 0 0" xyz="-0.008513 0.02068 -0.001088"/>
      <inertia ixx="0.014598842" ixy="-0.00066764" ixz="-3.629e-05" iyy="0.006452136" iyz="-8.283e-05" izz="0.016848319"/>
    </inertial>
    <visual>
      <geometry>
        <mesh filename="package://val_desc/model/meshes/arms/aj2_left.dae"/>
      </geometry>
      <origin rpy="0.0 0.0 0.0" xyz="0.0 0.0 0.0"/>
    </visual>
    <collision name="leftShoulderRollLink_test">
      <geometry>
        <cylinder radius="0.06" length="0.186"/>
      </geometry>
      <origin rpy="1.57 0 0" xyz="0 0.145 0"/>
    </collision>
    <collision_checking>
      <capsule name="leftShoulderRollLink_test"/>
    </collision_checking>
  </link>
  <link name="leftShoulderYawLink">
    <inertial>
      <mass value="3.085"/>
      <origin rpy="0 0 0" xyz="-0.004304 0.209832 0.007295"/>
      <inertia ixx="0.039355177" ixy="-0.007827077" ixz="-0.000753947" iyy="0.004905765" iyz="0.002723873" izz="0.041879481"/>
    </inertial>
    <visual>
      <geometry>
        <mesh filename="package://val_desc/model/meshes/arms/aj3_left.dae"/>
      </geometry>
      <origin rpy="0.0 0.0 0.0" xyz="0.0 0.0 0.0"/>
    </visual>
  </link>
  <link name="leftElbowPitchLink">
    <inertial>
      <mass value="1.83"/>
      <origin rpy="0 0 0" xyz="-0.020344 0.014722 0.0223"/>
      <inertia ixx="0.003314516" ixy="0.000535099" ixz="0.000728077" iyy="0.003505669" iyz="-0.000423865" izz="0.003011283"/>
    </inertial>
    <visual>
      <geometry>
        <mesh filename="package://val_desc/model/meshes/arms/aj4_left.dae"/>
      </geometry>
      <origin rpy="0.0 0.0 0.0" xyz="0.0 0.0 0.0"/>
    </visual>
  </link>
  <joint name="leftShoulderPitch" type="revolute">
    <origin rpy="0.0 0.0 0.0" xyz="-0.0316 0.0 0.2984"/>
    <axis xyz="0 1 0"/>
    <parent link="torso"/>
    <child link="leftShoulderPitchLink"/>
    <limit effort="190" lower="-2.85" upper="2.0" velocity="5.89"/>
    <controller_gains Kd="0.0" Ki="0.0" Kp="0.0"/>
    <dynamics damping="0.1" friction="0.0"/>
  </joint>
  <gazebo reference="leftShoulderPitch">
    <provideFeedback>1</provideFeedback>
    <implicitSpringDamper>1</implicitSpringDamper>
  </gazebo>
  <joint name="leftShoulderRoll" type="revolute">
    <origin rpy="0.0 0.0 0.0" xyz="0.0 0.2499 0.0"/>
    <axis xyz="1 0 0"/>
    <parent link="leftShoulderPitchLink"/>
    <child link="leftShoulderRollLink"/>
    <limit effort="190" lower="-1.519" upper="1.266" velocity="5.89"/>
    <controller_gains Kd="0.0" Ki="0.0" Kp="0.0"/>
    <dynamics damping="0.1" friction="0.0"/>
  </joint>
  <gazebo reference="leftShoulderRoll">
    <provideFeedback>1</provideFeedback>
    <implicitSpringDamper>1</implicitSpringDamper>
  </gazebo>
  <joint name="leftShoulderYaw" type="revolute">
    <origin rpy="0.0 0.0 0.0" xyz="0.0 0.0 0.0"/>
    <axis xyz="0 1 0"/>
    <parent link="leftShoulderRollLink"/>
    <child link="leftShoulderYawLink"/>
    <limit effort="65" lower="-3.1" upper="2.18" velocity="11.5"/>
    <controller_gains Kd="0.0" Ki="0.0" Kp="0.0"/>
    <dynamics damping="0.1" friction="0.0"/>
  </joint>
  <gazebo reference="leftShoulderYaw">
    <provideFeedback>1</provideFeedback>
    <implicitSpringDamper>1</implicitSpringDamper>
  </gazebo>
  <joint name="leftElbowPitch" type="revolute">
    <origin rpy="0.0 0.0 0.0" xyz="0.0254 0.33 0.0"/>
    <axis xyz="0 0 1"/>
    <parent link="leftShoulderYawLink"/>
    <child link="leftElbowPitchLink"/>
    <limit effort="65" lower="-2.174" upper="0.12" velocity="11.5"/>
    <controller_gains Kd="0.0" Ki="0.0" Kp="0.0"/>
    <dynamics damping="0.1" friction="0.0"/>
  </joint>

  <joint name="leftElbowNear" type="fixed">
    <origin rpy="0.0 0.0 0.0" xyz="0.0254 0.33 0.0"/>
    <axis xyz="0 0 1"/>
    <parent link="leftShoulderYawLink"/>
    <child link="leftElbowNearLink"/>
  </joint>
  <link name="leftElbowNearLink">
    <inertial>
      <mass value="0.0"/>
      <origin rpy="0 0 0" xyz="0.0 0.0 0.0"/>
      <inertia ixx="0.0" ixy="0.0" ixz="0.0" iyy="0.0" iyz="0.0" izz="0.0"/>
    </inertial>
    <collision>
      <geometry>
        <sphere radius="0.085"/>
      </geometry>
      <origin rpy="0.0 0 0" xyz="-0.02 0.0 0"/>
    </collision>
  </link>

  <gazebo reference="leftElbowPitch">
    <provideFeedback>1</provideFeedback>
    <implicitSpringDamper>1</implicitSpringDamper>
  </gazebo>
  <link name="leftForearmLink">
    <inertial>
      <mass value="2.476"/>
      <origin rpy="0 0 0" xyz="0.015000 0.13 0.019564"/>
      <inertia ixx="0.01175543" ixy="0.001300853" ixz="-0.000727141" iyy="0.005071567" iyz="0.001695416" izz="0.011365657"/>
    </inertial>
    <visual>
      <geometry>
        <mesh filename="package://val_desc/model/meshes/arms/aj5_left.dae"/>
      </geometry>
      <origin rpy="0.0 0.0 0.0" xyz="0.0 0.0 0.0"/>
    </visual>
    <collision>
      <geometry>
        <cylinder radius="0.06" length="0.17"/>
      </geometry>
      <origin rpy="1.57 0 0" xyz="0 0.155 0"/>
    </collision>
  </link>
  <link name="leftWristRollLink">
    <inertial>
      <mass value="0.14"/>
      <origin rpy="0 0 0" xyz="0 0.0 0"/>
      <inertia ixx="3.0251e-05" ixy="1.25e-07" ixz="3.6e-08" iyy="3.772e-05" iyz="0.0" izz="9.395e-06"/>
    </inertial>
    <visual>
      <geometry>
        <mesh filename="package://val_desc/model/meshes/arms/aj6_left.dae"/>
      </geometry>
      <origin rpy="0.0 0.0 0.0" xyz="0.0 0.0 0.0"/>
    </visual>
  </link>
  <link name="leftPalm">
    <inertial>
      <mass value="0.712"/>
      <origin rpy="0 0 0" xyz="0.002954 0.052034 -0.000236"/>
      <inertia ixx="0.000943493" ixy="3.4393e-05" ixz="3.8828e-05" iyy="0.000711024" iyz="-2.3429e-05" izz="0.000610199"/>
    </inertial>
    <visual>
      <geometry>
        <mesh filename="package://val_desc/model/meshes/arms/palm_left.dae"/>
      </geometry>
      <origin rpy="0.0 0.0 0.0" xyz="0.0 0.0 0.0"/>
    </visual>
    <collision>
      <geometry>
        <box size="0.05 0.075 0.0685"/>
      </geometry>
      <origin rpy="0 0 0" xyz="0.0075 0.06 0.0"/>
    </collision>
  </link>
  <joint name="leftForearmYaw" type="revolute">
    <origin rpy="0.0 0.0 0.0" xyz="-0.0254 0 0"/>
    <axis xyz="0 1 0"/>
    <parent link="leftElbowPitchLink"/>
    <child link="leftForearmLink"/>
    <limit effort="26" lower="-2.019" upper="3.14" velocity="5"/>
    <controller_gains Kd="0" Ki="0.0" Kp="0.0"/>
    <dynamics damping="0.1" friction="0.0"/>
  </joint>
  <gazebo reference="leftForearmYaw">
    <provideFeedback>1</provideFeedback>
    <implicitSpringDamper>1</implicitSpringDamper>
  </gazebo>
  <joint name="leftWristRoll" type="revolute">
    <origin rpy="0.0 0.0 0.0" xyz="0.0 0.2871 0.0"/>
    <axis xyz="1 0 0"/>
    <parent link="leftForearmLink"/>
    <child link="leftWristRollLink"/>
    <!-- <limit effort="14" lower="-0.62" upper="0.625" velocity="1"/> -->
    <limit effort="14" lower="-3.14" upper="3.14" velocity="1"/>
    <controller_gains Kd="400" Ki="0.0" Kp="20000"/>
    <dynamics damping="0.1" friction="0.0"/>
  </joint>
  <gazebo reference="leftWristRoll">
    <provideFeedback>1</provideFeedback>
    <implicitSpringDamper>1</implicitSpringDamper>
  </gazebo>
  <joint name="leftWristPitch" type="revolute">
    <origin rpy="0.0 0.0 0.0" xyz="0.0 0.0 0.0"/>
    <axis xyz="0 0 1"/>
    <parent link="leftWristRollLink"/>
    <child link="leftPalm"/>
    <!-- <limit effort="14" lower="-0.36" upper="0.49" velocity="1"/> -->
    <limit effort="14" lower="-3.14" upper="3.14" velocity="1"/>
    <controller_gains Kd="400" Ki="0.0" Kp="20000"/>
    <dynamics damping="0.1" friction="0.0"/>
  </joint>
  <gazebo reference="leftWristPitch">
    <provideFeedback>1</provideFeedback>
    <implicitSpringDamper>1</implicitSpringDamper>
  </gazebo>

  <link name="rightHipYawLink">
    <inertial>
      <mass value="2.39"/>
      <origin rpy="0 0 0" xyz="0.02176 0.00131 0.03867"/>
      <inertia ixx="0.017260978" ixy="0.0" ixz="0.0" iyy="0.014866198" iyz="0.0" izz="0.011238178"/>
    </inertial>
    <visual>
      <geometry>
        <mesh filename="package://val_desc/model/meshes/legs/lj1_right.dae"/>
      </geometry>
      <origin rpy="0.0 0.0 0.0" xyz="0.0 0.0 0.0"/>
    </visual>
  </link>
  <link name="rightHipRollLink">
    <inertial>
      <mass value="3.665"/>
      <origin rpy="0 0 0" xyz="0.012959 -0.00755 -0.015950"/>
      <inertia ixx="0.005978962" ixy="0.000234823" ixz="0.000553962" iyy="0.009372646" iyz="-0.000778956" izz="0.008193117"/>
    </inertial>
    <visual>
      <geometry>
        <mesh filename="package://val_desc/model/meshes/legs/lj2_right.dae"/>
      </geometry>
      <origin rpy="0.0 0.0 0.0" xyz="0.0 0.0 0.0"/>
    </visual>
  </link>

  <link name="rightHipUpperLink">
    <inertial>
      <mass value="10.2"/>
      <origin rpy="0 0 0" xyz="0.016691 -0.091397 -0.207875"/>
      <inertia ixx="0.24083413" ixy="-3.5915e-05" ixz="0.003699383" iyy="0.25689705" iyz="0.001333005" izz="0.023276352"/>
    </inertial>
    <collision name="rightHipPitchLink_upper">
      <geometry>
        <box size="0.125 0.065 0.19"/>
      </geometry>
      <origin rpy="0 0 0" xyz="0.01 -0.115 0.0"/>
    </collision>
  </link>

  <link name="rightHipPitchLink">
    <inertial>
      <mass value="10.2"/>
      <origin rpy="0 0 0" xyz="0.016691 -0.091397 -0.207875"/>
      <inertia ixx="0.24083413" ixy="-3.5915e-05" ixz="0.003699383" iyy="0.25689705" iyz="0.001333005" izz="0.023276352"/>
    </inertial>
    <visual>
      <geometry>
        <mesh filename="package://val_desc/model/meshes/legs/lj3_right.dae"/>
      </geometry>
      <origin rpy="0.0 0.0 0.0" xyz="0.0 0.0 0.0"/>
    </visual>
    <collision name="rightHipPitchLink_lower">
      <geometry>
        <cylinder radius="0.075" length="0.25"/>
      </geometry>
      <origin rpy="0 0 0" xyz="0.0225 -0.085 -0.3"/>
    </collision>
  </link>


  <link name="rightKneePitchLink">
    <inertial>
      <mass value="6.2"/>
      <origin rpy="0 0 0" xyz="-0.022183  0.001703  -0.189418"/>
      <inertia ixx="0.086935683" ixy="9.929e-05" ixz="0.000573207" iyy="0.091584066" iyz="0.000313745" izz="0.014017272"/>
    </inertial>
    <visual>
      <geometry>
        <mesh filename="package://val_desc/model/meshes/legs/lj4_right.dae"/>
      </geometry>
      <origin rpy="0.0 0.0 0.0" xyz="0.0 0.0 0.0"/>
    </visual>
    <collision>
      <geometry>
        <cylinder radius="0.07" length="0.26"/>
      </geometry>
      <origin rpy="0 0 0" xyz="0 0 -0.23"/>
    </collision>
  </link>
  <link name="rightAnklePitchLink">
    <inertial>
      <mass value="0.03"/>
      <origin rpy="0 0 0" xyz="0.0 0.0 0.0"/>
      <inertia ixx="4.377e-06" ixy="0.0" ixz="0.0" iyy="4.322e-06" iyz="0.0" izz="7.015e-06"/>
    </inertial>
    <visual>
      <geometry>
        <mesh filename="package://val_desc/model/meshes/legs/lj5.dae"/>
      </geometry>
      <origin rpy="0.0 0.0 0.0" xyz="0.0 0.0 0.0"/>
    </visual>
  </link>
  <link name="rightFoot">
    <inertial>
      <mass value="2.27"/>
      <origin rpy="0 0 0" xyz="0.037702  0.005161  -0.047634"/>
      <inertia ixx="0.00623936" ixy="0.000217174" ixz="0.001340587" iyy="0.017786991" iyz="-0.000187749" izz="0.020774433"/>
    </inertial>
    <visual>
      <geometry>
        <mesh filename="package://val_desc/model/meshes/legs/foot.dae"/>
      </geometry>
      <origin rpy="0 0 0" xyz="0 0 0"/>
    </visual>
    <collision>
      <geometry>
        <box size="0.27 0.16 0.064"/>
      </geometry>
      <origin rpy="0.0 0.0 0.0" xyz="0.066 0.0 -0.056"/>
    </collision>
  </link>
  <joint name="rightHipYaw" type="revolute">
    <origin rpy="0.0 0.0 0.0" xyz="0.0 -0.1016 -0.1853"/>
    <axis xyz="0 0 1"/>
    <parent link="pelvis"/>
    <child link="rightHipYawLink"/>
    <limit effort="190" lower="-1.1" upper="0.4141" velocity="5.89"/>
    <controller_gains Kd="0.0" Ki="0.0" Kp="0.0"/>
    <dynamics damping="0.1" friction="0.0"/>
  </joint>
  <gazebo reference="rightHipYaw">
    <provideFeedback>1</provideFeedback>
    <implicitSpringDamper>1</implicitSpringDamper>
  </gazebo>
  <joint name="rightHipRoll" type="revolute">
    <origin rpy="0.0 0.0 0.0" xyz="0.0 0.0 0.0"/>
    <axis xyz="1 0 0"/>
    <parent link="rightHipYawLink"/>
    <child link="rightHipRollLink"/>
    <limit effort="350" lower="-0.5515" upper="0.467" velocity="7"/>
    <controller_gains Kd="0.0" Ki="0.0" Kp="0.0"/>
    <dynamics damping="0.1" friction="0.0"/>
  </joint>
  <gazebo reference="rightHipRoll">
    <provideFeedback>1</provideFeedback>
    <implicitSpringDamper>1</implicitSpringDamper>
  </gazebo>

  <joint name="rightHipUpper" type="fixed">
    <origin rpy="0.0 0.0 0.0" xyz="0.0 0.0 -0.0609"/>
    <axis xyz="0 1 0"/>
    <parent link="rightHipPitchLink"/>
    <child link="rightHipUpperLink"/>
    <limit effort="350" lower="-2.42" upper="1.619" velocity="6.11"/>
    <controller_gains Kd="0.0" Ki="0.0" Kp="0.0"/>
    <dynamics damping="0.1" friction="0.0"/>
  </joint>

  <joint name="rightHipPitch" type="revolute">
    <origin rpy="0.0 0.0 0.0" xyz="0.0 0.0 -0.0609"/>
    <axis xyz="0 1 0"/>
    <parent link="rightHipRollLink"/>
    <child link="rightHipPitchLink"/>
    <limit effort="350" lower="-2.42" upper="1.619" velocity="6.11"/>
    <controller_gains Kd="0.0" Ki="0.0" Kp="0.0"/>
    <dynamics damping="0.1" friction="0.0"/>
  </joint>


  <gazebo reference="rightHipPitch">
    <provideFeedback>1</provideFeedback>
    <implicitSpringDamper>1</implicitSpringDamper>
  </gazebo>
  <joint name="rightKneePitch" type="revolute">
    <origin rpy="0.0 0.0 0.0" xyz="0.000112225 -0.0361046 -0.430959"/>
    <axis xyz="0 1 0"/>
    <parent link="rightHipPitchLink"/>
    <child link="rightKneePitchLink"/>
    <limit effort="350" lower="-0.083" upper="2.057" velocity="6.11"/>
    <controller_gains Kd="0.0" Ki="0.0" Kp="0.0"/>
    <dynamics damping="0.1" friction="0.0"/>
  </joint>

  <joint name="rightKneeNear" type="fixed">
    <origin rpy="0.0 0.0 0.0" xyz="0.000112225 -0.0361046 -0.430959"/>
    <axis xyz="0 1 0"/>
    <parent link="rightHipPitchLink"/>
    <child link="rightKneeNearLink"/>
  </joint>
  <link name="rightKneeNearLink">
    <inertial>
      <mass value="0.0"/>
      <origin rpy="0 0 0" xyz="0.0 0.0 0.0"/>
      <inertia ixx="0.0" ixy="0.0" ixz="0.0" iyy="0.0" iyz="0.0" izz="0.0"/>
    </inertial>
    <collision>
      <geometry>
        <sphere radius="0.095"/>
      </geometry>
      <origin rpy="0.0 0 0" xyz="0.01 -0.025 0.0"/>
    </collision>
  </link>

  <gazebo reference="rightKneePitch">
    <provideFeedback>1</provideFeedback>
    <implicitSpringDamper>1</implicitSpringDamper>
  </gazebo>
  <joint name="rightAnklePitch" type="revolute">
    <origin rpy="0.0 0.0 0.0" xyz="-0.0102381 0.0 -0.40627"/>
    <axis xyz="0 1 0"/>
    <parent link="rightKneePitchLink"/>
    <child link="rightAnklePitchLink"/>
    <!-- <limit effort="205" lower="-0.8644" upper="0.875" velocity="11"/> -->
    <limit effort="205" lower="-1.8644" upper="1.875" velocity="11"/>
    <controller_gains Kd="0.0" Ki="0.0" Kp="0.0"/>
    <dynamics damping="0.1" friction="0.0"/>
  </joint>
  <gazebo reference="rightAnklePitch">
    <provideFeedback>1</provideFeedback>
    <implicitSpringDamper>1</implicitSpringDamper>
  </gazebo>
  <joint name="rightAnkleRoll" type="revolute">
    <origin rpy="0.0 0.0 0.0" xyz="0.0 0.0 0.0"/>
    <axis xyz="1 0 0"/>
    <parent link="rightAnklePitchLink"/>
    <child link="rightFoot"/>
    <!-- <limit effort="205" lower="-0.349" upper="0.348" velocity="11"/> -->
    <limit effort="205" lower="-1.349" upper="1.348" velocity="11"/>
    <controller_gains Kd="0.0" Ki="0.0" Kp="0.0"/>
    <dynamics damping="0.3" friction="0.0"/>
  </joint>
  <gazebo reference="rightAnkleRoll">
    <provideFeedback>1</provideFeedback>
    <implicitSpringDamper>1</implicitSpringDamper>
  </gazebo>
  <link name="leftHipYawLink">
    <inertial>
      <mass value="2.39"/>
      <origin rpy="0 0 0" xyz="0.02176 -0.00131 0.03867"/>
      <inertia ixx="0.017260978" ixy="0.0" ixz="0.0" iyy="0.014866198" iyz="0.0" izz="0.011238178"/>
    </inertial>
    <visual>
      <geometry>
        <mesh filename="package://val_desc/model/meshes/legs/lj1_left.dae"/>
      </geometry>
      <origin rpy="0.0 0.0 0.0" xyz="0.0 0.0 0.0"/>
    </visual>
  </link>
  <link name="leftHipRollLink">
    <inertial>
      <mass value="3.665"/>
      <origin rpy="0 0 0" xyz="0.012959 0.00755 -0.015950"/>
      <inertia ixx="0.005978962" ixy="-0.000234823" ixz="0.000553962" iyy="0.009372646" iyz="0.000778956" izz="0.008193117"/>
    </inertial>
    <visual>
      <geometry>
        <mesh filename="package://val_desc/model/meshes/legs/lj2_left.dae"/>
      </geometry>
      <origin rpy="0.0 0.0 0.0" xyz="0.0 0.0 0.0"/>
    </visual>
  </link>

  <link name="leftHipUpperLink">
    <inertial>
      <mass value="10.2"/>
      <origin rpy="0 0 0" xyz="0.016691 0.091397 -0.207875"/>
      <inertia ixx="0.24083413" ixy="3.5915e-05" ixz="0.003699383" iyy="0.25689705" iyz="-0.001333005" izz="0.023276352"/>
    </inertial>
    <collision name="leftHipPitchLink_upper">
      <geometry>
        <box size="0.125 0.065 0.19"/>
      </geometry>
      <origin rpy="0 0 0" xyz="0.01 0.115 0.0"/>
    </collision>
  </link>

  <link name="leftHipPitchLink">
    <inertial>
      <mass value="10.2"/>
      <origin rpy="0 0 0" xyz="0.016691 0.091397 -0.207875"/>
      <inertia ixx="0.24083413" ixy="3.5915e-05" ixz="0.003699383" iyy="0.25689705" iyz="-0.001333005" izz="0.023276352"/>
    </inertial>
    <visual>
      <geometry>
        <mesh filename="package://val_desc/model/meshes/legs/lj3_left.dae"/>
      </geometry>
      <origin rpy="0.0 0.0 0.0" xyz="0.0 0.0 0.0"/>
    </visual>
    <collision name="leftHipPitchLink_lower">
      <geometry>
        <cylinder radius="0.075" length="0.25"/>
      </geometry>
      <origin rpy="0 0 0" xyz="0.0225 0.085 -0.3"/>
    </collision>
  </link>


  <link name="leftKneePitchLink">
    <inertial>
      <mass value="6.2"/>
      <origin rpy="0 0 0" xyz="-0.022183  0.001703  -0.189418"/>
      <inertia ixx="0.086935683" ixy="9.929e-05" ixz="0.000573207" iyy="0.091584066" iyz="0.000313745" izz="0.014017272"/>
    </inertial>
    <visual>
      <geometry>
        <mesh filename="package://val_desc/model/meshes/legs/lj4_left.dae"/>
      </geometry>
      <origin rpy="0.0 0.0 0.0" xyz="0.0 0.0 0.0"/>
    </visual>
    <collision>
      <geometry>
        <cylinder radius="0.07" length="0.26"/>
      </geometry>
      <origin rpy="0 0 0" xyz="0 0 -0.23"/>
    </collision>
  </link>
  <link name="leftAnklePitchLink">
    <inertial>
      <mass value="0.03"/>
      <origin rpy="0 0 0" xyz="0.0 0.0 0.0"/>
      <inertia ixx="4.377e-06" ixy="0.0" ixz="0.0" iyy="4.322e-06" iyz="0.0" izz="7.015e-06"/>
    </inertial>
    <visual>
      <geometry>
        <mesh filename="package://val_desc/model/meshes/legs/lj5.dae"/>
      </geometry>
      <origin rpy="0.0 0.0 0.0" xyz="0.0 0.0 0.0"/>
    </visual>
  </link>
  <link name="leftFoot">
    <inertial>
      <mass value="2.27"/>
      <origin rpy="0 0 0" xyz="0.037702  0.005161  -0.047634"/>
      <inertia ixx="0.00623936" ixy="0.000217174" ixz="0.001340587" iyy="0.017786991" iyz="-0.000187749" izz="0.020774433"/>
    </inertial>
    <visual>
      <geometry>
        <mesh filename="package://val_desc/model/meshes/legs/foot.dae"/>
      </geometry>
      <origin rpy="0 0 0" xyz="0 0 0"/>
    </visual>
    <collision>
      <geometry>
        <box size="0.27 0.16 0.064"/>
      </geometry>
      <origin rpy="0.0 0.0 0.0" xyz="0.066 0.0 -0.056"/>
    </collision>
  </link>
  <joint name="leftHipYaw" type="revolute">
    <origin rpy="0.0 0.0 0.0" xyz="0.0 0.1016 -0.1853"/>
    <axis xyz="0 0 1"/>
    <parent link="pelvis"/>
    <child link="leftHipYawLink"/>
    <limit effort="190" lower="-0.4141" upper="1.1" velocity="5.89"/>
    <controller_gains Kd="0.0" Ki="0.0" Kp="0.0"/>
    <dynamics damping="0.1" friction="0.0"/>
  </joint>
  <gazebo reference="leftHipYaw">
    <provideFeedback>1</provideFeedback>
    <implicitSpringDamper>1</implicitSpringDamper>
  </gazebo>
  <joint name="leftHipRoll" type="revolute">
    <origin rpy="0.0 0.0 0.0" xyz="0.0 0.0 0.0"/>
    <axis xyz="1 0 0"/>
    <parent link="leftHipYawLink"/>
    <child link="leftHipRollLink"/>
    <limit effort="350" lower="-0.467" upper="0.5515" velocity="7"/>
    <controller_gains Kd="0.0" Ki="0.0" Kp="0.0"/>
    <dynamics damping="0.1" friction="0.0"/>
  </joint>
  <gazebo reference="leftHipRoll">
    <provideFeedback>1</provideFeedback>
    <implicitSpringDamper>1</implicitSpringDamper>
  </gazebo>

  <joint name="leftHipUpper" type="fixed">
    <origin rpy="0.0 0.0 0.0" xyz="0.0 0.0 -0.0609"/>
    <axis xyz="0 1 0"/>
    <parent link="leftHipPitchLink"/>
    <child link="leftHipUpperLink"/>
    <limit effort="350" lower="-2.42" upper="1.619" velocity="6.11"/>
    <controller_gains Kd="0.0" Ki="0.0" Kp="0.0"/>
    <dynamics damping="0.1" friction="0.0"/>
  </joint>

  <joint name="leftHipPitch" type="revolute">
    <origin rpy="0.0 0.0 0.0" xyz="0.0 0.0 -0.0609"/>
    <axis xyz="0 1 0"/>
    <parent link="leftHipRollLink"/>
    <child link="leftHipPitchLink"/>
    <limit effort="350" lower="-2.42" upper="1.619" velocity="6.11"/>
    <controller_gains Kd="0.0" Ki="0.0" Kp="0.0"/>
    <dynamics damping="0.1" friction="0.0"/>
  </joint>


  <gazebo reference="leftHipPitch">
    <provideFeedback>1</provideFeedback>
    <implicitSpringDamper>1</implicitSpringDamper>
  </gazebo>
  <joint name="leftKneePitch" type="revolute">
    <origin rpy="0.0 0.0 0.0" xyz="0.000112225 0.0361046 -0.430959"/>
    <axis xyz="0 1 0"/>
    <parent link="leftHipPitchLink"/>
    <child link="leftKneePitchLink"/>
    <limit effort="350" lower="-0.083" upper="2.057" velocity="6.11"/>
    <controller_gains Kd="0.0" Ki="0.0" Kp="0.0"/>
    <dynamics damping="0.1" friction="0.0"/>
  </joint>

  <joint name="leftKneeNear" type="fixed">
    <origin rpy="0.0 0.0 0.0" xyz="0.000112225 0.0361046 -0.430959"/>
    <axis xyz="0 1 0"/>
    <parent link="leftHipPitchLink"/>
    <child link="leftKneeNearLink"/>
  </joint>
  <link name="leftKneeNearLink">
    <inertial>
      <mass value="0.0"/>
      <origin rpy="0 0 0" xyz="0.0 0.0 0.0"/>
      <inertia ixx="0.0" ixy="0.0" ixz="0.0" iyy="0.0" iyz="0.0" izz="0.0"/>
    </inertial>
    <collision>
      <geometry>
        <sphere radius="0.095"/>
      </geometry>
      <origin rpy="0.0 0 0" xyz="0.01 0.025 0.0"/>
    </collision>
  </link>

  <gazebo reference="leftKneePitch">
    <provideFeedback>1</provideFeedback>
    <implicitSpringDamper>1</implicitSpringDamper>
  </gazebo>
  <joint name="leftAnklePitch" type="revolute">
    <origin rpy="0.0 0.0 0.0" xyz="-0.0102381 0.0 -0.40627"/>
    <axis xyz="0 1 0"/>
    <parent link="leftKneePitchLink"/>
    <child link="leftAnklePitchLink"/>
    <!-- <limit effort="205" lower="-0.8644" upper="0.875" velocity="11"/> -->
    <limit effort="205" lower="-1.8644" upper="1.875" velocity="11"/>
    <controller_gains Kd="0.0" Ki="0.0" Kp="0.0"/>
    <dynamics damping="0.1" friction="0.0"/>
  </joint>
  <gazebo reference="leftAnklePitch">
    <provideFeedback>1</provideFeedback>
    <implicitSpringDamper>1</implicitSpringDamper>
  </gazebo>
  <joint name="leftAnkleRoll" type="revolute">
    <origin rpy="0.0 0.0 0.0" xyz="0.0 0.0 0.0"/>
    <axis xyz="1 0 0"/>
    <parent link="leftAnklePitchLink"/>
    <child link="leftFoot"/>
    <!-- <limit effort="205" lower="-0.349" upper="0.348" velocity="11"/> -->
    <limit effort="205" lower="-1.349" upper="1.348" velocity="11"/>
    <controller_gains Kd="0.0" Ki="0.0" Kp="0.0"/>
    <dynamics damping="0.3" friction="0.0"/>
  </joint>
  <gazebo reference="leftAnkleRoll">
    <provideFeedback>1</provideFeedback>
    <implicitSpringDamper>1</implicitSpringDamper>
  </gazebo>

  <link name="leftCOP_Frame">
    <inertial>
      <mass value="0.1"/>
      <origin rpy="0 0 0" xyz="0 0 0"/>
      <inertia ixx="8.33333333333e-05" ixy="0.0" ixz="0.0" iyy="8.33333333333e-05" iyz="0.0" izz="0.000125"/>
    </inertial>
  </link>
  <joint name="leftCOP_Offset" type="fixed">
    <!-- <origin rpy="0.0 0.0 0.0" xyz="0.0189 0.0 -0.0783"/> -->
    <origin rpy="0.0 0.0 0.0" xyz="0.037702 0.005161 -0.087634"/>
    <axis xyz="0 0 1"/>
    <parent link="leftFoot"/>
    <child link="leftCOP_Frame"/>
  </joint>


  <gazebo reference="leftCOP_Offset">
    <implicitSpringDamper>1</implicitSpringDamper>
  </gazebo>
  <gazebo reference="leftAnkleRoll">
    <sensor name="leftFootSixAxis" type="force_torque">
      <pose>0.0215646 0.0 -0.051054 3.14 0.0 0.0</pose>
      <sensor_number id="FT001SIM"/>
      <node id="/sensors/leftFootSixAxis"/>
      <api name="TurbodriverForceTorqueSensor"/>
      <always_on>true</always_on>
      <update_rate>1000</update_rate>
      <force_torque>
        <frame>sensor</frame>
      </force_torque>
    </sensor>
  </gazebo>
  <link name="rightCOP_Frame">
    <inertial>
      <mass value="0.1"/>
      <origin rpy="0 0 0" xyz="0 0 0"/>
      <inertia ixx="8.33333333333e-05" ixy="0.0" ixz="0.0" iyy="8.33333333333e-05" iyz="0.0" izz="0.000125"/>
    </inertial>
  </link>
  <joint name="rightCOP_Offset" type="fixed">
    <!-- <origin rpy="0.0 0.0 0.0" xyz="0.0189 0.0 -0.0783"/> -->
    <origin rpy="0.0 0.0 0.0" xyz="0.037702 0.005161 -0.087634"/>
    <axis xyz="0 0 1"/>
    <parent link="rightFoot"/>
    <child link="rightCOP_Frame"/>
  </joint>

  <gazebo reference="rightAnkleRoll">
    <sensor name="rightFootSixAxis" type="force_torque">
      <pose>0.0215646 0.0 -0.051054 3.14 0.0 0.0</pose>
      <sensor_number id="FT001SIM"/>
      <node id="/sensors/rightFootSixAxis"/>
      <api name="TurbodriverForceTorqueSensor"/>
      <always_on>true</always_on>
      <update_rate>1000</update_rate>
      <force_torque>
        <frame>sensor</frame>
      </force_torque>
    </sensor>
  </gazebo>
  <joint name="multisense_head_root_joint" type="fixed">
    <origin rpy="-3.14159 0.130899694 0.0" xyz="0.183585961 0.0 0.075353826"/>
    <!-- <origin rpy="-3.14159 0.130899694 0.0" xyz="0.183585961 0.0 0.275353826"/> -->
    <axis xyz="0 0 1"/>
    <parent link="upperNeckPitchLink"/>
    <child link="head"/>
  </joint>
  <gazebo reference="multisense_head_root_joint">
    <implicitSpringDamper>1</implicitSpringDamper>
  </gazebo>

</robot>
